Workbook
Name Building_Type_List: Site_Energy_No_Model!$C$30:$C$110
Name Building_Type_Table: Site_Energy_No_Model!$C$30:$Q$110
Name Contract_Date_List: LookupData!$AI$1:$AI$2
Name Contract_Length_List: IFERROR(IF(ISBLANK('Renewable Energy'!$E1),Select_Contract_Length,IF('Renewable Energy'!$E1="Owned","N/A (owned)",Select_Contract_Length)),Select_Contract_Length)
Name Contract_Years: IFERROR('Renewable Energy'!$F1^2/'Renewable Energy'!$F1,IFERROR(VLOOKUP('Renewable Energy'!$F1,Years_Lookup,2,FALSE),1))
Name Default_Cooling_Units: IF(IP_SI_Units="IP Units","Ton Hours","kWh")
Name Default_Elec_Units: IF(IP_SI_Units="IP Units","kWh","kWh")
Name Default_Electricity_No_Model: Site_Energy_No_Model!$J$21
Name Default_Fuel_No_Model: Site_Energy_No_Model!$K$21
Name Default_Fuel_Units: IF(IP_SI_Units="IP Units","therm","kWh")
Name Default_Gen_Type: IFERROR(IF(ISBLANK('Renewable Energy'!$C1),"",VLOOKUP('Renewable Energy'!$C1,Renewable_Source_Table,2,FALSE)),"Electricity")
Name Default_Heating_Units: IF(IP_SI_Units="IP Units","Btu x 10^6","kWh")
Name Default_Renewable_Units: IF(ISBLANK('Renewable Energy'!$C1),"",IFERROR(VLOOKUP('Renewable Energy'!$D1,Site_Energy_Table,3,FALSE),Default_Total_Units))
Name Default_Total_Units: IF(IP_SI_Units="IP Units","Btu x 10^6","MWh")
Name Energy_Units_List: LookupData!$G$2:$G$8
Name Energy_Units_Table: LookupData!$G$2:$H$8
Name IP_SI_Units: Instructions!$J$8
Name LEED_Renewable_Category: LookupData!$A$2:$A$4
Name Lookup_RatingSystem: LookupData!$BJ$2:$BJ$12
Name Lookup_Tier1_Points: LookupData!$AR$3:$AU$53
Name Lookup_Tier2_Points: LookupData!$AS$3:$AU$53
Name Lookup_Tier3_Points: LookupData!$AT$3:$AU$33
Name NA_owned: LookupData!$AE$14:$AE$15
Name Renewable_Location_Table: LookupData!$M$3:$O$6
Name Renewable_Source_Table: LookupData!$V$21:$W$40
Name Select_Contract_Length: LookupData!$AE$2:$AE$14
Name Site_Energy_Table: 'Renewable Energy'!$B$13:$D$17
Name TableRatingSystem: LookupData!$BJ$2:$BK$12
Name Tier1_Location_List: LookupData!$M$4:$M$6
Name Tier1_Procurement_Type: LookupData!$R$2:$R$5
Name Tier1_Renewable_Type: LookupData!$V$2:$V$15
Name Tier2_3_Location_List: LookupData!$N$4:$N$6
Name Tier2_Procurement_Type: LookupData!$S$2:$S$10
Name Tier2_Renewable_Type: LookupData!$Y$2:$Y$9
Name Tier3_Procurement_Type: LookupData!$T$2:$T$10
Name Tier3_Renewable_Type: LookupData!$AA$2:$AA$11
Name Units_Consumption: LookupData!$G$2:$G$8
Name Years_Lookup: LookupData!$AE$2:$AF$14

Sheet Instructions
E3: Renewable Energy Calculator LEED v4.1 EA Credit Renewable Energy
E5: Note: This calculator is for use with Excel for Mac 2011 and Excel 2007 or later.
E7: Step 1.
E8: Unit of measurement | J8: IP units
E9: Note: This selection must match the unit of measurement chosen during project registration.
E11: Step 2.
E12: Select the Rating System | H12: BD+C: New Construction
E15: Step 3.
E16: If an energy model was not completed for EAp Minimum Energy Performance,
E17: complete the Site_Energy_No_Model tab.
E19: Step 4.
E20: Complete the Renewable Energy tab.
E22: Step 4.
E23: Upload the completed spreadsheet to LEED Online. Complete any related summary fields in the LEED credit form with the results of the calculator, and upload all other required documentation.
K26: V04 | M26: UOM
K27: Copyright © 2024 | M27: =IF(J8="IP units",1,2) -> 1
K28: U.S. Green Building Council | M28: IP = 1, SI = 2
K29: All Rights Reserved
K30: Last Updated July 2024 | M30: CONCATENATE
M31: =IF(M27=1,"(sq ft)","(sq m)") -> (sq ft)

Sheet Renewable Energy
B2: Renewable Energy
B5: PROJECT SITE ENERGY USE
B6: If the project has an energy model for EAp Minimum Energy Performance, enter the total proposed annual site energy consumption per energy type (with exceptional calculation method)
B7: from the LEED v4.1 Minimum Energy Performance Calculator (MEPC) Table 12.10.
B9: If the project has no energy model, complete the "Site_Energy_No_Model" tab, and then select "Default_Electricity_No_Model" and "Default_Fuel_No_Model" below.
B11: Energy Type | C11: Proposed Site Energy
C12: (per energy source) | D12: Units | X12: kWh
B13: =LookupData!E2 -> Electricity | C13: =+Default_Electricity_No_Model -> 0 | D13: {=+Default_Elec_Units} -> kWh | X13: =IFERROR(C13*VLOOKUP(D13,Energy_Units_Table,2,FALSE),0) -> 0
B14: =LookupData!E3 -> Fossil Fuel | C14: =+Default_Fuel_No_Model -> 0 | D14: {=+Default_Fuel_Units} -> therm | X14: =IFERROR(C14*VLOOKUP(D14,Energy_Units_Table,2,FALSE),0) -> 0
B15: =LookupData!E4 -> District Cooling | D15: {=+Default_Cooling_Units} -> Ton Hours | X15: =IFERROR(C15*VLOOKUP(D15,Energy_Units_Table,2,FALSE),0) -> 0
B16: =LookupData!E5 -> District Heating | D16: {=+Default_Heating_Units} -> Btu x 10^6 | X16: =IFERROR(C16*VLOOKUP(D16,Energy_Units_Table,2,FALSE),0) -> 0
B17: =LookupData!E6 -> Other | D17: {=+Default_Total_Units} -> Btu x 10^6 | X17: =IFERROR(C17*VLOOKUP(D17,Energy_Units_Table,2,FALSE),0) -> 0
B18: Total | C18: =IFERROR(X18/VLOOKUP(D18,Energy_Units_Table,2,FALSE),0) -> 0 | D18: {=+Default_Total_Units} -> Btu x 10^6 | X18: =SUM(X13:X17) -> 0
B19: Total District Energy | C19: =IFERROR(X19/VLOOKUP(D19,Energy_Units_Table,2,FALSE),0) -> 0 | D19: =D18 -> Btu x 10^6 | X19: =SUM(X15,X16) -> 0
B20: Total Electricity + District Energy | C20: =IFERROR(X20/VLOOKUP(D20,Energy_Units_Table,2,FALSE),0) -> 0 | D20: =D18 -> Btu x 10^6 | X20: =SUM(X13,X15,X16) -> 0
B21: Total Fossil Fuel + Other | C21: =IFERROR(X21/VLOOKUP(D21,Energy_Units_Table,2,FALSE),0) -> 0 | D21: =D18 -> Btu x 10^6 | X21: =SUM(X14+X17) -> 0
B23: RENEWABLE ENERGY GENERATION:
B24: Complete all fields of the table for all renewable energy sources allocated to the project.
B25: Renewable Energy Category | C25: Renewable Energy Type | D25: Energy Offset Type | E25: Renewable Energy Procurement Type | F25: Length of Contract (Years) | G25: Renewable Location | H25: Contract execution date | I25: Generator "New Date" (or date contracted / designed to come online) | J25: Green-e Certified (or equivalent eco-label)? | L25: Annual Renewable Generation (Site Energy) | Q25: Annual Renewable Percent of Site Energy
L26: Annual Renewable Generation (for a one-time purchase enter total purchase amount) | M26: Quantity of annual renewable attributes used to satisfy Renewable Portfolio Standard (RPS) / mandatory renewable capacity policies. (0 if N/A) | N26: Qualifying Annual Renewable Generation with EACs retained | O26: Units of Energy | Q26: Percent of Electricity | R26: Percent of District Energy | S26: Percent of Fossil Fuel + Other | T26: Qualifying Percent of Total Annual Site Energy | W26: kWh - Annual with RECs retained | X26: kWh - Qualifying Annual
A27: =IFERROR(MATCH($B27,LEED_Renewable_Category,0),"") | D27: {=+Default_Gen_Type} | N27: =IFERROR(IF($L27>0,IF(AND($A27=2,$W27>$X$20),IF($J27="Yes",(($L27-$M27)*Contract_Years/10),($X$20/VLOOKUP($O27,Energy_Units_Table,2,FALSE)*Contract_Years/10)),IF(OR($A27=1,$A27=2,$J27="Yes",$C27<>"Electricity"),(($L27-$M27)*Contract_Years/10),"")),""),"") | O27: {=+Default_Renewable_Units} | Q27: =IF(ISBLANK($L27),"",IFERROR(IF($D27="Electricity",IF($A27=1,$X27/$X$13,MIN($X27/$X$13,100%)),""),"")) | R27: =IF(ISBLANK($L27),"",IFERROR(IF($D27="Electricity",MIN(MAX($X27-$X$13,0)/$X$19,100%),IF($D27="Fossil Fuel",MIN(MAX($X27-$X$21,0)/$X$19,100%),MIN($X27/$X$19,100%))),"")) | S27: =IF(ISBLANK($L27),"",IFERROR(IF($D27<>"Electricity",MIN($X27/$X$21,100%),""),"")) | T27: =IFERROR(IF($A27=1,$X27/$X$18,IF(AND($A27=2,$D27="Electricity"),MIN(MIN($X27,$X$20)/$X$18,100%),MIN(IF($D27="Electricity",MIN($X27,$X$20)/$X$18,MIN($X27,$X$19+$X$21)/$X$18),100%))),"") | W27: =IFERROR((L27-M27)*VLOOKUP(O27,Energy_Units_Table,2,FALSE),0) -> 0 | X27: =IFERROR(N27*VLOOKUP(O27,Energy_Units_Table,2,FALSE),0) -> 0 | AA27: =IFERROR(IF(ISBLANK('Renewable Energy'!$B27),"",VLOOKUP('Renewable Energy'!$B27,Renewable_Source_Table,2,FALSE)),"Electricity")
A28: =IFERROR(MATCH($B28,LEED_Renewable_Category,0),"") | D28: {=+Default_Gen_Type} | N28: =IFERROR(IF($L28>0,IF(AND($A28=2,$W28>$X$20),IF($J28="Yes",(($L28-$M28)*Contract_Years/10),($X$20/VLOOKUP($O28,Energy_Units_Table,2,FALSE)*Contract_Years/10)),IF(OR($A28=1,$A28=2,$J28="Yes",$C28<>"Electricity"),(($L28-$M28)*Contract_Years/10),"")),""),"") | O28: {=+Default_Renewable_Units} | Q28: =IF(ISBLANK($L28),"",IFERROR(IF($D28="Electricity",IF($A28=1,$X28/$X$13,MIN($X28/$X$13,100%)),""),"")) | R28: =IF(ISBLANK($L28),"",IFERROR(IF($D28="Electricity",MIN(MAX($X28-$X$13,0)/$X$19,100%),IF($D28="Fossil Fuel",MIN(MAX($X28-$X$21,0)/$X$19,100%),MIN($X28/$X$19,100%))),"")) | S28: =IF(ISBLANK($L28),"",IFERROR(IF($D28<>"Electricity",MIN($X28/$X$21,100%),""),"")) | T28: =IFERROR(IF($A28=1,$X28/$X$18,IF(AND($A28=2,$D28="Electricity"),MIN(MIN($X28,$X$20)/$X$18,100%),MIN(IF($D28="Electricity",MIN($X28,$X$20)/$X$18,MIN($X28,$X$19+$X$21)/$X$18),100%))),"") | W28: =IFERROR((L28-M28)*VLOOKUP(O28,Energy_Units_Table,2,FALSE),0) -> 0 | X28: =IFERROR(N28*VLOOKUP(O28,Energy_Units_Table,2,FALSE),0) -> 0
A29: =IFERROR(MATCH($B29,LEED_Renewable_Category,0),"") | D29: {=+Default_Gen_Type} | N29: =IFERROR(IF($L29>0,IF(AND($A29=2,$W29>$X$20),IF($J29="Yes",(($L29-$M29)*Contract_Years/10),($X$20/VLOOKUP($O29,Energy_Units_Table,2,FALSE)*Contract_Years/10)),IF(OR($A29=1,$A29=2,$J29="Yes",$C29<>"Electricity"),(($L29-$M29)*Contract_Years/10),"")),""),"") | O29: {=+Default_Renewable_Units} | Q29: =IF(ISBLANK($L29),"",IFERROR(IF($D29="Electricity",IF($A29=1,$X29/$X$13,MIN($X29/$X$13,100%)),""),"")) | R29: =IF(ISBLANK($L29),"",IFERROR(IF($D29="Electricity",MIN(MAX($X29-$X$13,0)/$X$19,100%),IF($D29="Fossil Fuel",MIN(MAX($X29-$X$21,0)/$X$19,100%),MIN($X29/$X$19,100%))),"")) | S29: =IF(ISBLANK($L29),"",IFERROR(IF($D29<>"Electricity",MIN($X29/$X$21,100%),""),"")) | T29: =IFERROR(IF($A29=1,$X29/$X$18,IF(AND($A29=2,$D29="Electricity"),MIN(MIN($X29,$X$20)/$X$18,100%),MIN(IF($D29="Electricity",MIN($X29,$X$20)/$X$18,MIN($X29,$X$19+$X$21)/$X$18),100%))),"") | W29: =IFERROR((L29-M29)*VLOOKUP(O29,Energy_Units_Table,2,FALSE),0) -> 0 | X29: =IFERROR(N29*VLOOKUP(O29,Energy_Units_Table,2,FALSE),0) -> 0
A30: =IFERROR(MATCH($B30,LEED_Renewable_Category,0),"") | D30: {=+Default_Gen_Type} | N30: =IFERROR(IF($L30>0,IF(AND($A30=2,$W30>$X$20),IF($J30="Yes",(($L30-$M30)*Contract_Years/10),($X$20/VLOOKUP($O30,Energy_Units_Table,2,FALSE)*Contract_Years/10)),IF(OR($A30=1,$A30=2,$J30="Yes",$C30<>"Electricity"),(($L30-$M30)*Contract_Years/10),"")),""),"") | O30: {=+Default_Renewable_Units} | Q30: =IF(ISBLANK($L30),"",IFERROR(IF($D30="Electricity",IF($A30=1,$X30/$X$13,MIN($X30/$X$13,100%)),""),"")) | R30: =IF(ISBLANK($L30),"",IFERROR(IF($D30="Electricity",MIN(MAX($X30-$X$13,0)/$X$19,100%),IF($D30="Fossil Fuel",MIN(MAX($X30-$X$21,0)/$X$19,100%),MIN($X30/$X$19,100%))),"")) | S30: =IF(ISBLANK($L30),"",IFERROR(IF($D30<>"Electricity",MIN($X30/$X$21,100%),""),"")) | T30: =IFERROR(IF($A30=1,$X30/$X$18,IF(AND($A30=2,$D30="Electricity"),MIN(MIN($X30,$X$20)/$X$18,100%),MIN(IF($D30="Electricity",MIN($X30,$X$20)/$X$18,MIN($X30,$X$19+$X$21)/$X$18),100%))),"") | W30: =IFERROR((L30-M30)*VLOOKUP(O30,Energy_Units_Table,2,FALSE),0) -> 0 | X30: =IFERROR(N30*VLOOKUP(O30,Energy_Units_Table,2,FALSE),0) -> 0
A31: =IFERROR(MATCH($B31,LEED_Renewable_Category,0),"") | D31: {=+Default_Gen_Type} | N31: =IFERROR(IF($L31>0,IF(AND($A31=2,$W31>$X$20),IF($J31="Yes",(($L31-$M31)*Contract_Years/10),($X$20/VLOOKUP($O31,Energy_Units_Table,2,FALSE)*Contract_Years/10)),IF(OR($A31=1,$A31=2,$J31="Yes",$C31<>"Electricity"),(($L31-$M31)*Contract_Years/10),"")),""),"") | O31: {=+Default_Renewable_Units} | Q31: =IF(ISBLANK($L31),"",IFERROR(IF($D31="Electricity",IF($A31=1,$X31/$X$13,MIN($X31/$X$13,100%)),""),"")) | R31: =IF(ISBLANK($L31),"",IFERROR(IF($D31="Electricity",MIN(MAX($X31-$X$13,0)/$X$19,100%),IF($D31="Fossil Fuel",MIN(MAX($X31-$X$21,0)/$X$19,100%),MIN($X31/$X$19,100%))),"")) | S31: =IF(ISBLANK($L31),"",IFERROR(IF($D31<>"Electricity",MIN($X31/$X$21,100%),""),"")) | T31: =IFERROR(IF($A31=1,$X31/$X$18,IF(AND($A31=2,$D31="Electricity"),MIN(MIN($X31,$X$20)/$X$18,100%),MIN(IF($D31="Electricity",MIN($X31,$X$20)/$X$18,MIN($X31,$X$19+$X$21)/$X$18),100%))),"") | W31: =IFERROR((L31-M31)*VLOOKUP(O31,Energy_Units_Table,2,FALSE),0) -> 0 | X31: =IFERROR(N31*VLOOKUP(O31,Energy_Units_Table,2,FALSE),0) -> 0
A32: =IFERROR(MATCH($B32,LEED_Renewable_Category,0),"") | D32: {=+Default_Gen_Type} | N32: =IFERROR(IF($L32>0,IF(AND($A32=2,$W32>$X$20),IF($J32="Yes",(($L32-$M32)*Contract_Years/10),($X$20/VLOOKUP($O32,Energy_Units_Table,2,FALSE)*Contract_Years/10)),IF(OR($A32=1,$A32=2,$J32="Yes",$C32<>"Electricity"),(($L32-$M32)*Contract_Years/10),"")),""),"") | O32: {=+Default_Renewable_Units} | Q32: =IF(ISBLANK($L32),"",IFERROR(IF($D32="Electricity",IF($A32=1,$X32/$X$13,MIN($X32/$X$13,100%)),""),"")) | R32: =IF(ISBLANK($L32),"",IFERROR(IF($D32="Electricity",MIN(MAX($X32-$X$13,0)/$X$19,100%),IF($D32="Fossil Fuel",MIN(MAX($X32-$X$21,0)/$X$19,100%),MIN($X32/$X$19,100%))),"")) | S32: =IF(ISBLANK($L32),"",IFERROR(IF($D32<>"Electricity",MIN($X32/$X$21,100%),""),"")) | T32: =IFERROR(IF($A32=1,$X32/$X$18,IF(AND($A32=2,$D32="Electricity"),MIN(MIN($X32,$X$20)/$X$18,100%),MIN(IF($D32="Electricity",MIN($X32,$X$20)/$X$18,MIN($X32,$X$19+$X$21)/$X$18),100%))),"") | W32: =IFERROR((L32-M32)*VLOOKUP(O32,Energy_Units_Table,2,FALSE),0) -> 0 | X32: =IFERROR(N32*VLOOKUP(O32,Energy_Units_Table,2,FALSE),0) -> 0
A33: =IFERROR(MATCH($B33,LEED_Renewable_Category,0),"") | D33: {=+Default_Gen_Type} | N33: =IFERROR(IF($L33>0,IF(AND($A33=2,$W33>$X$20),IF($J33="Yes",(($L33-$M33)*Contract_Years/10),($X$20/VLOOKUP($O33,Energy_Units_Table,2,FALSE)*Contract_Years/10)),IF(OR($A33=1,$A33=2,$J33="Yes",$C33<>"Electricity"),(($L33-$M33)*Contract_Years/10),"")),""),"") | O33: {=+Default_Renewable_Units} | Q33: =IF(ISBLANK($L33),"",IFERROR(IF($D33="Electricity",IF($A33=1,$X33/$X$13,MIN($X33/$X$13,100%)),""),"")) | R33: =IF(ISBLANK($L33),"",IFERROR(IF($D33="Electricity",MIN(MAX($X33-$X$13,0)/$X$19,100%),IF($D33="Fossil Fuel",MIN(MAX($X33-$X$21,0)/$X$19,100%),MIN($X33/$X$19,100%))),"")) | S33: =IF(ISBLANK($L33),"",IFERROR(IF($D33<>"Electricity",MIN($X33/$X$21,100%),""),"")) | T33: =IFERROR(IF($A33=1,$X33/$X$18,IF(AND($A33=2,$D33="Electricity"),MIN(MIN($X33,$X$20)/$X$18,100%),MIN(IF($D33="Electricity",MIN($X33,$X$20)/$X$18,MIN($X33,$X$19+$X$21)/$X$18),100%))),"") | W33: =IFERROR((L33-M33)*VLOOKUP(O33,Energy_Units_Table,2,FALSE),0) -> 0 | X33: =IFERROR(N33*VLOOKUP(O33,Energy_Units_Table,2,FALSE),0) -> 0
A34: =IFERROR(MATCH($B34,LEED_Renewable_Category,0),"") | D34: {=+Default_Gen_Type} | N34: =IFERROR(IF($L34>0,IF(AND($A34=2,$W34>$X$20),IF($J34="Yes",(($L34-$M34)*Contract_Years/10),($X$20/VLOOKUP($O34,Energy_Units_Table,2,FALSE)*Contract_Years/10)),IF(OR($A34=1,$A34=2,$J34="Yes",$C34<>"Electricity"),(($L34-$M34)*Contract_Years/10),"")),""),"") | O34: {=+Default_Renewable_Units} | Q34: =IF(ISBLANK($L34),"",IFERROR(IF($D34="Electricity",IF($A34=1,$X34/$X$13,MIN($X34/$X$13,100%)),""),"")) | R34: =IF(ISBLANK($L34),"",IFERROR(IF($D34="Electricity",MIN(MAX($X34-$X$13,0)/$X$19,100%),IF($D34="Fossil Fuel",MIN(MAX($X34-$X$21,0)/$X$19,100%),MIN($X34/$X$19,100%))),"")) | S34: =IF(ISBLANK($L34),"",IFERROR(IF($D34<>"Electricity",MIN($X34/$X$21,100%),""),"")) | T34: =IFERROR(IF($A34=1,$X34/$X$18,IF(AND($A34=2,$D34="Electricity"),MIN(MIN($X34,$X$20)/$X$18,100%),MIN(IF($D34="Electricity",MIN($X34,$X$20)/$X$18,MIN($X34,$X$19+$X$21)/$X$18),100%))),"") | W34: =IFERROR((L34-M34)*VLOOKUP(O34,Energy_Units_Table,2,FALSE),0) -> 0 | X34: =IFERROR(N34*VLOOKUP(O34,Energy_Units_Table,2,FALSE),0) -> 0
A35: =IFERROR(MATCH($B35,LEED_Renewable_Category,0),"") | D35: {=+Default_Gen_Type} | N35: =IFERROR(IF($L35>0,IF(AND($A35=2,$W35>$X$20),IF($J35="Yes",(($L35-$M35)*Contract_Years/10),($X$20/VLOOKUP($O35,Energy_Units_Table,2,FALSE)*Contract_Years/10)),IF(OR($A35=1,$A35=2,$J35="Yes",$C35<>"Electricity"),(($L35-$M35)*Contract_Years/10),"")),""),"") | O35: {=+Default_Renewable_Units} | Q35: =IF(ISBLANK($L35),"",IFERROR(IF($D35="Electricity",IF($A35=1,$X35/$X$13,MIN($X35/$X$13,100%)),""),"")) | R35: =IF(ISBLANK($L35),"",IFERROR(IF($D35="Electricity",MIN(MAX($X35-$X$13,0)/$X$19,100%),IF($D35="Fossil Fuel",MIN(MAX($X35-$X$21,0)/$X$19,100%),MIN($X35/$X$19,100%))),"")) | S35: =IF(ISBLANK($L35),"",IFERROR(IF($D35<>"Electricity",MIN($X35/$X$21,100%),""),"")) | T35: =IFERROR(IF($A35=1,$X35/$X$18,IF(AND($A35=2,$D35="Electricity"),MIN(MIN($X35,$X$20)/$X$18,100%),MIN(IF($D35="Electricity",MIN($X35,$X$20)/$X$18,MIN($X35,$X$19+$X$21)/$X$18),100%))),"") | W35: =IFERROR((L35-M35)*VLOOKUP(O35,Energy_Units_Table,2,FALSE),0) -> 0 | X35: =IFERROR(N35*VLOOKUP(O35,Energy_Units_Table,2,FALSE),0) -> 0
A36: =IFERROR(MATCH($B36,LEED_Renewable_Category,0),"") | D36: {=+Default_Gen_Type} | N36: =IFERROR(IF($L36>0,IF(AND($A36=2,$W36>$X$20),IF($J36="Yes",(($L36-$M36)*Contract_Years/10),($X$20/VLOOKUP($O36,Energy_Units_Table,2,FALSE)*Contract_Years/10)),IF(OR($A36=1,$A36=2,$J36="Yes",$C36<>"Electricity"),(($L36-$M36)*Contract_Years/10),"")),""),"") | O36: {=+Default_Renewable_Units} | Q36: =IF(ISBLANK($L36),"",IFERROR(IF($D36="Electricity",IF($A36=1,$X36/$X$13,MIN($X36/$X$13,100%)),""),"")) | R36: =IF(ISBLANK($L36),"",IFERROR(IF($D36="Electricity",MIN(MAX($X36-$X$13,0)/$X$19,100%),IF($D36="Fossil Fuel",MIN(MAX($X36-$X$21,0)/$X$19,100%),MIN($X36/$X$19,100%))),"")) | S36: =IF(ISBLANK($L36),"",IFERROR(IF($D36<>"Electricity",MIN($X36/$X$21,100%),""),"")) | T36: =IFERROR(IF($A36=1,$X36/$X$18,IF(AND($A36=2,$D36="Electricity"),MIN(MIN($X36,$X$20)/$X$18,100%),MIN(IF($D36="Electricity",MIN($X36,$X$20)/$X$18,MIN($X36,$X$19+$X$21)/$X$18),100%))),"") | W36: =IFERROR((L36-M36)*VLOOKUP(O36,Energy_Units_Table,2,FALSE),0) -> 0 | X36: =IFERROR(N36*VLOOKUP(O36,Energy_Units_Table,2,FALSE),0) -> 0
A38: A | B38: Total Tier 1: On-site renewable energy | L38: =IFERROR(LookupData!$BQ$3,"") | M38: Points | N38: =IFERROR(X38/VLOOKUP(O38,Energy_Units_Table,2,FALSE),0) -> 0 | O38: =$D$20 -> Btu x 10^6 | Q38: =IFERROR(SUMIF($A$27:$A$36,1,Q$27:Q$36),"") -> 0 | R38: =IFERROR(SUMIF($A$27:$A$36,1,R$27:R$36),"") -> 0 | S38: =IFERROR(SUMIF($A$27:$A$36,1,S$27:S$36),"") -> 0 | T38: =IFERROR(SUMIF($A$27:$A$36,1,T$27:T$36),"") -> 0 | W38: =MIN(SUMIF($A$27:$A$36,1,$X$27:$X$36),W20) -> 0 | X38: =MIN(SUMIF($A$27:$A$36,1,$X$27:$X$36),X20) -> 0
B39: Total Tier 2. New Off-site renewable electricity | L39: =IFERROR(LookupData!$BR$3,"") | M39: Points | N39: =IFERROR(X39/VLOOKUP(O39,Energy_Units_Table,2,FALSE),0) -> 0 | O39: =$D$20 -> Btu x 10^6 | Q39: =IFERROR(MIN(SUMIF($A$27:$A$36,2,Q$27:Q$36),100%-MIN(Q38,100%)),"") -> 0 | R39: =IFERROR(MIN(SUMIF($A$27:$A$36,2,R$27:R$36),100%-MIN(R38,100%)),"") -> 0 | S39: =IFERROR(MIN(SUMIF($A$27:$A$36,2,S$27:S$36),100%-MIN(S38,100%)),"") -> 0 | T39: =IFERROR(MIN(SUMIF($A$27:$A$36,2,T$27:T$36),100%-MIN(T38,100%)),"") -> 0 | W39: =SUMIF($A$27:$A$36,2,$X$27:$X$36) -> 0 | X39: =SUMIF($A$27:$A$36,2,$X$27:$X$36) -> 0
B40: Total Tier 3. Off-site renewable | L40: =IFERROR(LookupData!$BS$3,"") | M40: Points | N40: =IFERROR(X40/VLOOKUP(O40,Energy_Units_Table,2,FALSE),0) -> 0 | O40: =$D$20 -> Btu x 10^6 | Q40: =IFERROR(MIN(SUMIF($A$27:$A$36,3,Q$27:Q$36),100%-MIN(Q39+Q38,100%)),"") -> 0 | R40: =IFERROR(MIN(SUMIF($A$27:$A$36,3,R$27:R$36),100%-MIN(R39+R38,100%)),"") -> 0 | S40: =IFERROR(MIN(SUMIF($A$27:$A$36,3,S$27:S$36),100%-MIN(S39+S38,100%)),"") -> 0 | T40: =IFERROR(MIN(SUMIF($A$27:$A$36,3,T$27:T$36),100%-MIN(T39+T38,100%)),"") -> 0 | W40: =SUMIF($A$27:$A$36,3,$X$27:$X$36) -> 0 | X40: =SUMIF($A$27:$A$36,3,$X$27:$X$36) -> 0
B42: Total Renewable Energy (Tier 1-3). (Maximum of 5 for BD+C, 6 for ID+C; plus one Exemplary) | L42: =IFERROR(LookupData!$BU$3,"") -> 0 | M42: =IFERROR(IF(LookupData!$BV$3="EP","Points + 1 Exemplary","Points"),"") -> Points | N42: =IFERROR(X42/VLOOKUP(O42,Energy_Units_Table,2,FALSE),0) -> 0 | O42: =$D$20 -> Btu x 10^6 | Q42: =IFERROR(MIN(SUMIF($A$27:$A$36,3,Q$27:Q$36),100%-MIN(Q40+Q39,100%)),"") -> 0 | R42: =IFERROR(MIN(SUMIF($A$27:$A$36,3,R$27:R$36),100%-MIN(R40+R39,100%)),"") -> 0 | S42: =IFERROR(MIN(SUMIF($A$27:$A$36,3,S$27:S$36),100%-MIN(S40+S39,100%)),"") -> 0 | T42: =IFERROR(MIN(SUMIF($A$27:$A$36,3,T$27:T$36),100%-MIN(T40+T39,100%)),"") -> 0 | W42: =SUMIF($A$27:$A$36,3,$X$27:$X$36) -> 0 | X42: =SUMIF($A$27:$A$36,3,$X$27:$X$36) -> 0
B45: Notes:
B46: All environmental attributes associated with renewable energy generation must be retired on behalf of the LEED project in order for the renewable energy procurement to contribute to credit achievement.
B47: Tier 1. On-site renewable energy
B48: a. Documentation for EAp Fundamental Commissioning must be uploaded demonstrating that the on-site renewable system has been installed and commissioned.
B49: b. All renewable combustion sources (agricultural crops, bio-fuel, landfill gas, etc.) must be both captured (harvested) and used on-site to qualify as a Tier 1 renewable energy source.
B50: c. If the project shares on-site renewable sources with other buildings on a campus, and/or is located outside of the project boundary on a contiguous campus sharing ownership with the project owner,
...

Sheet Site_Energy_No_Model
B2: Renewable Energy
B7: Is the building all-electric (no combustion sources for heating, water heating, cooking, etc. in the project space and base building)? | K7: No
B9: SITE ENERGY DETERMINATION FOR BUILDINGS WITHOUT ENERGY MODELS
B10: Select all building types present in the project, and enter the associated gross area per building type.
B12: Building Type(s) | D12: Area | G12: Site Energy Use Intensity | J12: Annual Site Energy Use
D13: =IF(IP_SI_Units="IP Units","(square feet)","(square meters)") -> (square feet) | G13: =CONCATENATE("Electricity ", IF(IP_SI_Units="IP Units","(kWh/ft2)","(kWh/m2)")) -> Electricity (kWh/ft2) | H13: =CONCATENATE("Natural Gas ", IF(IP_SI_Units="IP Units","(kBtu/ft2)","(kWh/m2)")) -> Natural Gas (kBtu/ft2) | J13: =CONCATENATE("Electricity ", IF(IP_SI_Units="IP Units","(kWh)","(kWh)")) -> Electricity (kWh) | K13: =CONCATENATE("Natural Gas ", IF(IP_SI_Units="IP Units","(therms)","(kWh)")) -> Natural Gas (therms) | M13: =CONCATENATE("Total ", IF(IP_SI_Units="IP Units","(Btu x 10^6)","(MWh)")) -> Total (Btu x 10^6)
G14: =IFERROR(ROUND(IF(IP_SI_Units="IP Units",0.0929,1)*((VLOOKUP($B14,Building_Type_Table,11,FALSE)+IF($K$7="Yes",0.75*VLOOKUP($B14,Building_Type_Table,12,FALSE),0))),2),"") | H14: =IFERROR(ROUND(IF(IP_SI_Units="IP Units",0.0929*3.412,1)*IF(AND($D14>0,$K$7="Yes"),0,VLOOKUP($B14,Building_Type_Table,12,FALSE)),2),"") | J14: =IFERROR($D14*G14,"") | K14: =IFERROR(IF(IP_SI_Units="IP Units",1/100,1)*H14*$D14,"") | M14: =IFERROR(ROUND(IF(IP_SI_Units="IP Units",3.412/1000,1/1000)*J14+IF(IP_SI_Units="IP Units",1/10,1/1000)*K14,1),"")
G15: =IFERROR(ROUND(IF(IP_SI_Units="IP Units",0.0929,1)*((VLOOKUP($B15,Building_Type_Table,11,FALSE)+IF($K$7="Yes",0.75*VLOOKUP($B15,Building_Type_Table,12,FALSE),0))),2),"") | H15: =IFERROR(ROUND(IF(IP_SI_Units="IP Units",0.0929*3.412,1)*IF(AND($D15>0,$K$7="Yes"),0,VLOOKUP($B15,Building_Type_Table,12,FALSE)),2),"") | J15: =IFERROR($D15*G15,"") | K15: =IFERROR(IF(IP_SI_Units="IP Units",1/100,1)*H15*$D15,"") | M15: =IFERROR(ROUND(IF(IP_SI_Units="IP Units",3.412/1000,1/1000)*J15+IF(IP_SI_Units="IP Units",1/10,1/1000)*K15,1),"")
G16: =IFERROR(ROUND(IF(IP_SI_Units="IP Units",0.0929,1)*((VLOOKUP($B16,Building_Type_Table,11,FALSE)+IF($K$7="Yes",0.75*VLOOKUP($B16,Building_Type_Table,12,FALSE),0))),2),"") | H16: =IFERROR(ROUND(IF(IP_SI_Units="IP Units",0.0929*3.412,1)*IF(AND($D16>0,$K$7="Yes"),0,VLOOKUP($B16,Building_Type_Table,12,FALSE)),2),"") | J16: =IFERROR($D16*G16,"") | K16: =IFERROR(IF(IP_SI_Units="IP Units",1/100,1)*H16*$D16,"") | M16: =IFERROR(ROUND(IF(IP_SI_Units="IP Units",3.412/1000,1/1000)*J16+IF(IP_SI_Units="IP Units",1/10,1/1000)*K16,1),"")
G17: =IFERROR(ROUND(IF(IP_SI_Units="IP Units",0.0929,1)*((VLOOKUP($B17,Building_Type_Table,11,FALSE)+IF($K$7="Yes",0.75*VLOOKUP($B17,Building_Type_Table,12,FALSE),0))),2),"") | H17: =IFERROR(ROUND(IF(IP_SI_Units="IP Units",0.0929*3.412,1)*IF(AND($D17>0,$K$7="Yes"),0,VLOOKUP($B17,Building_Type_Table,12,FALSE)),2),"") | J17: =IFERROR($D17*G17,"") | K17: =IFERROR(IF(IP_SI_Units="IP Units",1/100,1)*H17*$D17,"") | M17: =IFERROR(ROUND(IF(IP_SI_Units="IP Units",3.412/1000,1/1000)*J17+IF(IP_SI_Units="IP Units",1/10,1/1000)*K17,1),"")
G18: =IFERROR(ROUND(IF(IP_SI_Units="IP Units",0.0929,1)*((VLOOKUP($B18,Building_Type_Table,11,FALSE)+IF($K$7="Yes",0.75*VLOOKUP($B18,Building_Type_Table,12,FALSE),0))),2),"") | H18: =IFERROR(ROUND(IF(IP_SI_Units="IP Units",0.0929*3.412,1)*IF(AND($D18>0,$K$7="Yes"),0,VLOOKUP($B18,Building_Type_Table,12,FALSE)),2),"") | J18: =IFERROR($D18*G18,"") | K18: =IFERROR(IF(IP_SI_Units="IP Units",1/100,1)*H18*$D18,"") | M18: =IFERROR(ROUND(IF(IP_SI_Units="IP Units",3.412/1000,1/1000)*J18+IF(IP_SI_Units="IP Units",1/10,1/1000)*K18,1),"")
G19: =IFERROR(ROUND(IF(IP_SI_Units="IP Units",0.0929,1)*((VLOOKUP($B19,Building_Type_Table,11,FALSE)+IF($K$7="Yes",0.75*VLOOKUP($B19,Building_Type_Table,12,FALSE),0))),2),"") | H19: =IFERROR(ROUND(IF(IP_SI_Units="IP Units",0.0929*3.412,1)*IF(AND($D19>0,$K$7="Yes"),0,VLOOKUP($B19,Building_Type_Table,12,FALSE)),2),"") | J19: =IFERROR($D19*G19,"") | K19: =IFERROR(IF(IP_SI_Units="IP Units",1/100,1)*H19*$D19,"") | M19: =IFERROR(ROUND(IF(IP_SI_Units="IP Units",3.412/1000,1/1000)*J19+IF(IP_SI_Units="IP Units",1/10,1/1000)*K19,1),"")
G20: =IFERROR(ROUND(IF(IP_SI_Units="IP Units",0.0929,1)*((VLOOKUP($B20,Building_Type_Table,11,FALSE)+IF($K$7="Yes",0.75*VLOOKUP($B20,Building_Type_Table,12,FALSE),0))),2),"") | H20: =IFERROR(ROUND(IF(IP_SI_Units="IP Units",0.0929*3.412,1)*IF(AND($D20>0,$K$7="Yes"),0,VLOOKUP($B20,Building_Type_Table,12,FALSE)),2),"") | J20: =IFERROR($D20*G20,"") | K20: =IFERROR(IF(IP_SI_Units="IP Units",1/100,1)*H20*$D20,"") | M20: =IFERROR(ROUND(IF(IP_SI_Units="IP Units",3.412/1000,1/1000)*J20+IF(IP_SI_Units="IP Units",1/10,1/1000)*K20,1),"")
B21: Total: | D21: =IFERROR(IF(SUM(D14:D20)>0,SUM(D14:D20),""),"") | J21: =IFERROR(IF($D21>0,SUM(J14:J20),""),"") -> 0 | K21: =IFERROR(IF($D21>0,SUM(K14:K20),""),"") -> 0 | M21: =IFERROR(IF($D21>0,SUM(M14:M20),""),"") -> 0 | N21: =IFERROR(IF($D21>0,SUM(N14:N20),""),"") -> 0
B23: ENERGY STAR PortfolioManager Technical Reference - U.S. Energy Use Intensity by Property Type
B24: Source for Total Source EUI and Site EUI (with non-electric sources): https://portfoliomanager.energystar.gov/pdf/reference/US%20National%20Median%20Table.pdf
B25: Electricity and natural gas were calculated based on total source energy and total site energy reported in the ENERGY STAR Portfolio Manager Technical Reference, and source-to-site ratios of 2.80 for electricity and 1.05 for natural gas.
D27: Buildings with non-electric sources serving project (e.g. heating, water heating, and/or cooking) | P27: All-Electric Buildings
D28: IP Units | J28: SI Units | P28: IP Units | Q28: SI Units
D29: Source EUI (kBtu/ft2) | E29: Site EUI (kBtu/ft2) | G29: Electricity (kBtu/ft2) | H29: Natural Gas (kBtu/ft2) | J29: Source EUI (kWh/m2) | K29: Site EUI (kWh/m2) | M29: Electricity (kWh/m2) | N29: Natural Gas (kWh/m2) | P29: Site Energy - Electricity (kWh/ft2) | Q29: Site Energy - Electricity (kWh/m2) | U29: % Electricity
B30: Banking Financial Services | C30: Bank Branch | D30: 209.9 | E30: 88.3 | G30: =(D30-LookupData!$AM$4*E30)/(LookupData!$AM$2-LookupData!$AM$4) -> 66.962857 | H30: =E30-G30 -> 21.337143 | J30: =D30*LookupData!$AN$10 -> 662.17608 | K30: =E30*LookupData!$AN$10 -> 278.56193 | M30: =G30*LookupData!$AN$10 -> 211.24918 | N30: =H30*LookupData!$AN$10 -> 67.312747 | P30: =(M30+N30*0.75)*LookupData!AN$7 -> 24.31586 | Q30: =(M30+N30*0.75) -> 261.73374 | U30: =ROUNDUP(M30/K30,2) -> 0.76
C31: Financial Office | D31: 116.4 | E31: 52.9 | G31: =(D31-LookupData!$AM$4*E31)/(LookupData!$AM$2-LookupData!$AM$4) -> 34.774286 | H31: =E31-G31 -> 18.125714 | J31: =D31*LookupData!$AN$10 -> 367.20961 | K31: =E31*LookupData!$AN$10 -> 166.88478 | M31: =G31*LookupData!$AN$10 -> 109.70319 | N31: =H31*LookupData!$AN$10 -> 57.181584 | P31: =(M31+N31*0.75)*LookupData!AN$7 -> 14.176017 | Q31: =(M31+N31*0.75) -> 152.58938 | U31: =ROUNDUP(M31/K31,2) -> 0.66
B32: Education | C32: Adult Education | D32: 110.4 | E32: 52.4 | G32: =(D32-LookupData!$AM$4*E32)/(LookupData!$AM$2-LookupData!$AM$4) -> 31.645714 | H32: =E32-G32 -> 20.754286 | J32: =D32*LookupData!$AN$10 -> 348.28127 | K32: =E32*LookupData!$AN$10 -> 165.30742 | M32: =G32*LookupData!$AN$10 -> 99.833421 | N32: =H32*LookupData!$AN$10 -> 65.473995 | P32: =(M32+N32*0.75)*LookupData!AN$7 -> 13.836878 | Q32: =(M32+N32*0.75) -> 148.93892 | U32: =ROUNDUP(M32/K32,2) -> 0.61
C33: College_University | D33: 180.6 | E33: 84.3 | G33: =(D33-LookupData!$AM$4*E33)/(LookupData!$AM$2-LookupData!$AM$4) -> 52.62 | H33: =E33-G33 -> 31.68 | J33: =D33*LookupData!$AN$10 -> 569.74274 | K33: =E33*LookupData!$AN$10 -> 265.94304 | M33: =G33*LookupData!$AN$10 -> 166.00146 | N33: =H33*LookupData!$AN$10 -> 99.941583 | P33: =(M33+N33*0.75)*LookupData!AN$7 -> 22.385698 | Q33: =(M33+N33*0.75) -> 240.95764 | U33: =ROUNDUP(M33/K33,2) -> 0.63
C34: K-12 School | D34: 104.4 | E34: 48.5 | G34: =(D34-LookupData!$AM$4*E34)/(LookupData!$AM$2-LookupData!$AM$4) -> 30.557143 | H34: =E34-G34 -> 17.942857 | J34: =D34*LookupData!$AN$10 -> 329.35294 | K34: =E34*LookupData!$AN$10 -> 153.004 | M34: =G34*LookupData!$AN$10 -> 96.399281 | N34: =H34*LookupData!$AN$10 -> 56.604721 | P34: =(M34+N34*0.75)*LookupData!AN$7 -> 12.899849 | Q34: =(M34+N34*0.75) -> 138.85282 | U34: =ROUNDUP(M34/K34,2) -> 0.64
C35: Pre-school _ Daycare | D35: 131.5 | E35: 64.8 | G35: =(D35-LookupData!$AM$4*E35)/(LookupData!$AM$2-LookupData!$AM$4) -> 36.262857 | H35: =E35-G35 -> 28.537143 | J35: =D35*LookupData!$AN$10 -> 414.8459 | K35: =E35*LookupData!$AN$10 -> 204.42597 | M35: =G35*LookupData!$AN$10 -> 114.39922 | N35: =H35*LookupData!$AN$10 -> 90.026744 | P35: =(M35+N35*0.75)*LookupData!AN$7 -> 16.900854 | Q35: =(M35+N35*0.75) -> 181.91928 | U35: =ROUNDUP(M35/K35,2) -> 0.56
C36: Vocational School | D36: 110.4 | E36: 52.4 | G36: =(D36-LookupData!$AM$4*E36)/(LookupData!$AM$2-LookupData!$AM$4) -> 31.645714 | H36: =E36-G36 -> 20.754286 | J36: =D36*LookupData!$AN$10 -> 348.28127 | K36: =E36*LookupData!$AN$10 -> 165.30742 | M36: =G36*LookupData!$AN$10 -> 99.833421 | N36: =H36*LookupData!$AN$10 -> 65.473995 | P36: =(M36+N36*0.75)*LookupData!AN$7 -> 13.836878 | Q36: =(M36+N36*0.75) -> 148.93892 | U36: =ROUNDUP(M36/K36,2) -> 0.61
C37: Other - Education | D37: 110.4 | E37: 52.4 | G37: =(D37-LookupData!$AM$4*E37)/(LookupData!$AM$2-LookupData!$AM$4) -> 31.645714 | H37: =E37-G37 -> 20.754286 | J37: =D37*LookupData!$AN$10 -> 348.28127 | K37: =E37*LookupData!$AN$10 -> 165.30742 | M37: =G37*LookupData!$AN$10 -> 99.833421 | N37: =H37*LookupData!$AN$10 -> 65.473995 | P37: =(M37+N37*0.75)*LookupData!AN$7 -> 13.836878 | Q37: =(M37+N37*0.75) -> 148.93892 | U37: =ROUNDUP(M37/K37,2) -> 0.61
B38: Entertainment / Public Assembly | C38: Convention Center | D38: 109.6 | E38: 56.1 | G38: =(D38-LookupData!$AM$4*E38)/(LookupData!$AM$2-LookupData!$AM$4) -> 28.968571 | H38: =E38-G38 -> 27.131429 | J38: =D38*LookupData!$AN$10 -> 345.7575 | K38: =E38*LookupData!$AN$10 -> 176.97989 | M38: =G38*LookupData!$AN$10 -> 91.387781 | N38: =H38*LookupData!$AN$10 -> 85.592106 | P38: =(M38+N38*0.75)*LookupData!AN$7 -> 14.454028 | Q38: =(M38+N38*0.75) -> 155.58186 | U38: =ROUNDUP(M38/K38,2) -> 0.52
C39: Movie Theater | D39: 112 | E39: 56.2 | G39: =(D39-LookupData!$AM$4*E39)/(LookupData!$AM$2-LookupData!$AM$4) -> 30.28 | H39: =E39-G39 -> 25.92 | J39: =D39*LookupData!$AN$10 -> 353.32883 | K39: =E39*LookupData!$AN$10 -> 177.29536 | M39: =G39*LookupData!$AN$10 -> 95.524973 | N39: =H39*LookupData!$AN$10 -> 81.770386 | P39: =(M39+N39*0.75)*LookupData!AN$7 -> 14.572098 | Q39: =(M39+N39*0.75) -> 156.85276 | U39: =ROUNDUP(M39/K39,2) -> 0.54
C40: Museum | D40: 112 | E40: 56.2 | G40: =(D40-LookupData!$AM$4*E40)/(LookupData!$AM$2-LookupData!$AM$4) -> 30.28 | H40: =E40-G40 -> 25.92 | J40: =D40*LookupData!$AN$10 -> 353.32883 | K40: =E40*LookupData!$AN$10 -> 177.29536 | M40: =G40*LookupData!$AN$10 -> 95.524973 | N40: =H40*LookupData!$AN$10 -> 81.770386 | P40: =(M40+N40*0.75)*LookupData!AN$7 -> 14.572098 | Q40: =(M40+N40*0.75) -> 156.85276 | U40: =ROUNDUP(M40/K40,2) -> 0.54
C41: Performing Arts | D41: 112 | E41: 56.2 | G41: =(D41-LookupData!$AM$4*E41)/(LookupData!$AM$2-LookupData!$AM$4) -> 30.28 | H41: =E41-G41 -> 25.92 | J41: =D41*LookupData!$AN$10 -> 353.32883 | K41: =E41*LookupData!$AN$10 -> 177.29536 | M41: =G41*LookupData!$AN$10 -> 95.524973 | N41: =H41*LookupData!$AN$10 -> 81.770386 | P41: =(M41+N41*0.75)*LookupData!AN$7 -> 14.572098 | Q41: =(M41+N41*0.75) -> 156.85276 | U41: =ROUNDUP(M41/K41,2) -> 0.54
C42: Social_Meeting Hall | D42: 109.6 | E42: 56.1 | G42: =(D42-LookupData!$AM$4*E42)/(LookupData!$AM$2-LookupData!$AM$4) -> 28.968571 | H42: =E42-G42 -> 27.131429 | J42: =D42*LookupData!$AN$10 -> 345.7575 | K42: =E42*LookupData!$AN$10 -> 176.97989 | M42: =G42*LookupData!$AN$10 -> 91.387781 | N42: =H42*LookupData!$AN$10 -> 85.592106 | P42: =(M42+N42*0.75)*LookupData!AN$7 -> 14.454028 | Q42: =(M42+N42*0.75) -> 155.58186 | U42: =ROUNDUP(M42/K42,2) -> 0.52
C43: Stadium | D43: 112 | E43: 56.2 | G43: =(D43-LookupData!$AM$4*E43)/(LookupData!$AM$2-LookupData!$AM$4) -> 30.28 | H43: =E43-G43 -> 25.92 | J43: =D43*LookupData!$AN$10 -> 353.32883 | K43: =E43*LookupData!$AN$10 -> 177.29536 | M43: =G43*LookupData!$AN$10 -> 95.524973 | N43: =H43*LookupData!$AN$10 -> 81.770386 | P43: =(M43+N43*0.75)*LookupData!AN$7 -> 14.572098 | Q43: =(M43+N43*0.75) -> 156.85276 | U43: =ROUNDUP(M43/K43,2) -> 0.54
C44: Bar_Nightclub | D44: 297 | E44: 130.7 | G44: =(D44-LookupData!$AM$4*E44)/(LookupData!$AM$2-LookupData!$AM$4) -> 91.294286 | H44: =E44-G44 -> 39.405714 | J44: =D44*LookupData!$AN$10 -> 936.95234 | K44: =E44*LookupData!$AN$10 -> 412.32213 | M44: =G44*LookupData!$AN$10 -> 288.00806 | N44: =H44*LookupData!$AN$10 -> 124.31406 | P44: =(M44+N44*0.75)*LookupData!AN$7 -> 35.41869 | Q44: =(M44+N44*0.75) -> 381.24361 | U44: =ROUNDUP(M44/K44,2) -> 0.7
C45: Other - Entertainment | D45: 112 | E45: 56.2 | G45: =(D45-LookupData!$AM$4*E45)/(LookupData!$AM$2-LookupData!$AM$4) -> 30.28 | H45: =E45-G45 -> 25.92 | J45: =D45*LookupData!$AN$10 -> 353.32883 | K45: =E45*LookupData!$AN$10 -> 177.29536 | M45: =G45*LookupData!$AN$10 -> 95.524973 | N45: =H45*LookupData!$AN$10 -> 81.770386 | P45: =(M45+N45*0.75)*LookupData!AN$7 -> 14.572098 | Q45: =(M45+N45*0.75) -> 156.85276 | U45: =ROUNDUP(M45/K45,2) -> 0.54
B46: Recreation - Entertainment | C46: Bowling Alley | D46: 112 | E46: 50.8 | G46: =(D46-LookupData!$AM$4*E46)/(LookupData!$AM$2-LookupData!$AM$4) -> 33.52 | H46: =E46-G46 -> 17.28 | J46: =D46*LookupData!$AN$10 -> 353.32883 | K46: =E46*LookupData!$AN$10 -> 160.25986 | M46: =G46*LookupData!$AN$10 -> 105.74627 | N46: =H46*LookupData!$AN$10 -> 54.513591 | P46: =(M46+N46*0.75)*LookupData!AN$7 -> 13.622509 | Q46: =(M46+N46*0.75) -> 146.63146 | U46: =ROUNDUP(M46/K46,2) -> 0.66
C47: Roller Rink | D47: 112 | E47: 50.8 | G47: =(D47-LookupData!$AM$4*E47)/(LookupData!$AM$2-LookupData!$AM$4) -> 33.52 | H47: =E47-G47 -> 17.28 | J47: =D47*LookupData!$AN$10 -> 353.32883 | K47: =E47*LookupData!$AN$10 -> 160.25986 | M47: =G47*LookupData!$AN$10 -> 105.74627 | N47: =H47*LookupData!$AN$10 -> 54.513591 | P47: =(M47+N47*0.75)*LookupData!AN$7 -> 13.622509 | Q47: =(M47+N47*0.75) -> 146.63146 | U47: =ROUNDUP(M47/K47,2) -> 0.66
C48: Ice _ Curling Rink | D48: 112 | E48: 50.8 | G48: =(D48-LookupData!$AM$4*E48)/(LookupData!$AM$2-LookupData!$AM$4) -> 33.52 | H48: =E48-G48 -> 17.28 | J48: =D48*LookupData!$AN$10 -> 353.32883 | K48: =E48*LookupData!$AN$10 -> 160.25986 | M48: =G48*LookupData!$AN$10 -> 105.74627 | N48: =H48*LookupData!$AN$10 -> 54.513591 | P48: =(M48+N48*0.75)*LookupData!AN$7 -> 13.622509 | Q48: =(M48+N48*0.75) -> 146.63146 | U48: =ROUNDUP(M48/K48,2) -> 0.66
C49: Roller Rink | D49: 112 | E49: 50.8 | G49: =(D49-LookupData!$AM$4*E49)/(LookupData!$AM$2-LookupData!$AM$4) -> 33.52 | H49: =E49-G49 -> 17.28 | J49: =D49*LookupData!$AN$10 -> 353.32883 | K49: =E49*LookupData!$AN$10 -> 160.25986 | M49: =G49*LookupData!$AN$10 -> 105.74627 | N49: =H49*LookupData!$AN$10 -> 54.513591 | P49: =(M49+N49*0.75)*LookupData!AN$7 -> 13.622509 | Q49: =(M49+N49*0.75) -> 146.63146 | U49: =ROUNDUP(M49/K49,2) -> 0.66
...

Sheet Summary
C3: Summary for Design and Construction Rating Systems
C4: Note: All information on this tab is READ-ONLY. To edit, see previous tabs.
C9: EA Credit Renewable Energy
C11: Tier 1: On-site renewable energy percent of annual project site energy use | H11: ='Renewable Energy'!T38 -> 0
C13: Tier 2. New Off-site renewable electricity percent of annual project site energy use | H13: ='Renewable Energy'!T39 -> 0
C15: Tier 3. Off-site renewable percent of annual project site energy use | H15: ='Renewable Energy'!T40 -> 0
C17: Points: | G17: =IFERROR(IF('Renewable Energy'!L42>0,'Renewable Energy'!L42,""),"") | H17: =IFERROR('Renewable Energy'!M42,"") -> Points

Sheet LookupData
A1: LEED Renewable Category | D1: Energy Generation Type | E1: Offset Energy type | G1: Energy Consumption Units | H1: convert to kWh | M1: Renewable Generator Location | Q1: Procurement Type | R1: Tier 1 | S1: Tier 2 | T1: Tier 3 | V1: Tier 1 On-site renewable sources | W1: Generation Type | Y1: Tier 2 Renewable Electricity Generation Sources | AA1: Tier 3 Renewable Generation Sources | AB1: Offset Energy type | AE1: Length of Contract (Years) | AI1: DD-Month-YY | AL1: Source-to-Site Ratios | AQ1: Table 1. Points for Renewable Energy Procurement - BD+C | AX1: Table 2. Points for CS | BD1: Table 3. Points for Renewable Energy Procurement - ID+C | BJ1: Rating System | BM1: Selected Rating System: | BQ1: Tier 1 | BR1: Tier 2 | BS1: Tier 3 | BU1: Total | BV1: EP?
A2: Tier 1. On-site renewable energy | B2: On-site renewable generation, environmental attributes (e.g. RECs) retained | D2: Electricity | E2: Electricity | G2: kWh | H2: 1 | M2: Tier 1 | N2: Tier 2 | O2: Tier 3 | Q2: Owned | R2: Owned | S2: Virtual Power Purchase Agreement (VPPA) | T2: Unbundled: Green-e EACs | V2: Photovoltaic | W2: Electricity | Y2: Photovoltaic | AA2: Photovoltaic | AB2: Electricity | AE2: One-time purchase | AF2: 1 | AL2: Electricity (Grid Purchase) | AM2: 2.8 | AQ2: Points | AR2: Tier 1 | AS2: Tier 2 | AT2: Tier 3 | AU2: NC Points | AX2: Points | AY2: Tier 1 | AZ2: Tier 2 | BA2: Tier 3 | BD2: Points | BE2: Tier 1 | BF2: Tier 2 | BG2: Tier 3 | BH2: ID+C Points | BJ2: BD+C: New Construction | BK2: BDC | BM2: {=IFERROR(VLOOKUP(Instructions!$H$12,TableRatingSystem,2,FALSE),BDC)} -> BDC | BP2: Percent | BQ2: ='Renewable Energy'!$T$38 -> 0 | BR2: ='Renewable Energy'!$T$39 -> 0 | BS2: ='Renewable Energy'!$T$40 -> 0 | BU2: ='Renewable Energy'!$T$42 -> 0
A3: Tier 2. New Off-site renewable electricity | B3: Off-site renewable electricity produced by generation asset(s) built within the last 5 years or contracted to be operational within 2 years of building occupancy | D3: Thermal | E3: Fossil Fuel | G3: MWh | H3: 1000 | M3: 1 | N3: 2 | O3: 3 | Q3: Leased | R3: Leased | S3: Feed-in Tariff | T3: Unbundled: Green-e equivalent EACs* | V3: Wind | W3: Electricity | Y3: Wind | AA3: Wind | AB3: Electricity | AE3: more than 10 | AF3: 10 | AL3: Electricity - On-site Wind or Solar | AM3: 1 | AQ3: 0 | AR3: 0 | AS3: 0 | AT3: 0 | AU3: =AQ3 -> 0 | AX3: 0 | AY3: 0 | AZ3: 0 | BA3: 0 | BB3: =AX3 -> 0 | BD3: 0 | BE3: 0 | BF3: 0 | BG3: 0 | BH3: =BD3 -> 0 | BJ3: BD+C: Core and Shell | BK3: CS | BP3: Points | BQ3: =IF($BM$2="CS",BQ$6,IF($BM$2="IDC",BQ$7,BQ$5)) | BR3: =IF($BM$2="CS",BR$6,IF($BM$2="IDC",BR$7,BR$5)) | BS3: =IF($BM$2="CS",BS$6,IF($BM$2="IDC",BS$7,BS$5)) | BU3: =IFERROR(IF($BM$2="CS",BU$6,IF($BM$2="IDC",BU$7,BU$5)),"") -> 0 | BV3: =IF($BM$2="CS",BV$6,IF($BM$2="IDC",BV$7,BV$5))
A4: Tier 3. Off-site renewable energy | B4: Off-site renewable electricity that is Green-e Energy certified or equivalent or captured bio-methane | E4: District Cooling | G4: kBtu | H4: 0.29308324 | M4: On site | N4: same country | O4: same country | Q4: Power Purchase Agreement (PPA) | R4: Power Purchase Agreement (PPA) | S4: Power Purchase Agreement (PPA) | T4: Utility 100% Green Power Tariff | V4: Solar thermal | W4: Thermal | Y4: Solar thermal electricity | AA4: Solar thermal electricity | AB4: Electricity | AE4: 10 | AF4: 10 | AL4: Natural Gas | AM4: 1.05 | AQ4: 0.1 | AR4: 0.0015 | AS4: =AQ4/10-0.0005 -> 0.0095 | AT4: =AU4*AT$13-0.0005 -> 0.03445 | AU4: =AQ4 -> 0.1 | AX4: =AX3+0.2 -> 0.2 | AY4: 0.0015 | AZ4: 0.0055 | BA4: 0.0195 | BB4: =AX4 -> 0.2 | BD4: 0.1 | BE4: 0.0015 | BF4: =BD4/10-0.0005 -> 0.0095 | BG4: =BH4*BG$13-0.0005 -> 0.02445 | BH4: =BD4 -> 0.1 | BJ4: BD+C: Schools | BK4: BDC
E5: District Heating | G5: therm | H5: 29.308324 | M5: On campus | N5: Same geographical region | O5: Same geographical region | Q5: Virtual Power Purchase Agreement (VPPA) | R5: Other-Describe | S5: Utility 100% Green Power Tariff | T5: Virtual Power Purchase Agreement (VPPA) | V5: On-site untreated wood waste - thermal* | W5: Thermal | Y5: Geothermal electricity* | AA5: Geothermal electricity* | AB5: Electricity | AE5: 9 | AF5: 9 | AQ5: =AQ4+0.1 -> 0.2 | AR5: 0.0035 | AS5: =AQ5/10-0.0005 -> 0.0195 | AT5: =AT4+2.5% -> 0.05945 | AU5: =AQ5 -> 0.2 | AX5: =AX4+0.2 -> 0.4 | AY5: 0.0035 | AZ5: 0.0115 | BA5: 0.0395 | BB5: =AX5 -> 0.4 | BD5: =BD4+0.1 -> 0.2 | BE5: 0.0035 | BF5: =BD5/10-0.0005 -> 0.0195 | BG5: =BG4+2.5% -> 0.04945 | BH5: =BD5 -> 0.2 | BJ5: BD+C: Retail | BK5: BDC | BP5: Points BDC | BQ5: =IFERROR(IF(BQ$2>0,VLOOKUP(BQ$2,Lookup_Tier1_Points,4),""),"") | BR5: =IFERROR(IF(BR$2>0,VLOOKUP(BR$2,Lookup_Tier2_Points,3),""),"") | BS5: =IFERROR(IF(BS$2>0,VLOOKUP(BS$2,Lookup_Tier3_Points,2),""),"") | BU5: =IFERROR(MIN(ROUNDDOWN(SUM(BQ5:BS5),0),5),"") -> 0 | BV5: =IF(OR($BQ$2>=25%,$BR$2>=60%,SUM(BQ5:BR5)>=6),"EP","")
E6: Other | G6: Btu x 10^6 | H6: 293.08324 | M6: Other - Describe | N6: Other - Describe | O6: Other - Describe | Q6: Feed-in Tariff | S6: Unbundled: Green-e EACs | T6: Feed-in Tariff | V6: On-site agricultural crops or waste - thermal* | W6: Thermal | Y6: Ocean-based (wave/tidal)* | AA6: Ocean-based (wave/tidal)* | AB6: Electricity | AE6: 8 | AF6: 8 | AQ6: =AQ5+0.1 -> 0.3 | AR6: 0.0055 | AS6: =AQ6/10-0.0005 -> 0.0295 | AT6: =AT5+2.5% -> 0.08445 | AU6: =AQ6 -> 0.3 | AX6: =AX5+0.2 -> 0.6 | AY6: 0.0055 | AZ6: 0.0175 | BA6: 0.0595 | BB6: =AX6 -> 0.6 | BD6: =BD5+0.1 -> 0.3 | BE6: 0.0055 | BF6: =BD6/10-0.0005 -> 0.0295 | BG6: =BG5+2.5% -> 0.07445 | BH6: =BD6 -> 0.3 | BJ6: BD+C: Healthcare | BK6: BDC | BP6: Points CS | BQ6: =IFERROR(IF(BQ$2>0,VLOOKUP(BQ$2,$AY$3:$BB$28,4),""),"") | BR6: =IFERROR(IF(BR$2>0,VLOOKUP(BR$2,$AZ$3:$BB$28,3),""),"") | BS6: =IFERROR(IF(BS$2>0,VLOOKUP(BS$2,$BA$3:$BB$18,2),""),"") | BU6: =IFERROR(MIN(ROUNDDOWN(SUM(BQ6:BS6),0),5),"") -> 0 | BV6: =IF(OR($BQ$2>=25%,$BR$2>=60%),"EP","")
G7: MJ | H7: 0.27784291 | Q7: Utility 100% Green Power Tariff | S7: Unbundled: Green-e equivalent EACs* | T7: Power Purchase Agreement (PPA) | V7: On-site animal or organic waste - thermal* | W7: Thermal | Y7: Low-impact hydropower* | AA7: Low-impact hydropower* | AB7: Electricity | AE7: 7 | AF7: 7 | AL7: IP Units | AM7: ft2 to m2 | AN7: =CONVERT(1,"ft","m")^2 -> 0.09290304 | AQ7: =AQ6+0.1 -> 0.4 | AR7: 0.0075 | AS7: =AQ7/10-0.0005 -> 0.0395 | AT7: =AT6+2.5% -> 0.10945 | AU7: =AQ7 -> 0.4 | AX7: =AX6+0.2 -> 0.8 | AY7: 0.0075 | AZ7: 0.0235 | BA7: 0.0795 | BB7: =AX7 -> 0.8 | BD7: =BD6+0.1 -> 0.4 | BE7: 0.0075 | BF7: =BD7/10-0.0005 -> 0.0395 | BG7: =BG6+2.5% -> 0.09945 | BH7: =BD7 -> 0.4 | BJ7: BD+C: Data Centers | BK7: BDC | BP7: Points IDC | BQ7: =IFERROR(IF(BQ$2>0,VLOOKUP(BQ$2,BE3:BH63,4),""),"") | BR7: =IFERROR(IF(BR$2>0,VLOOKUP(BR$2,BF3:BH63,3),""),"") | BS7: =IFERROR(IF(BS$2>0,VLOOKUP(BS$2,BG3:BH43,2),""),"") | BU7: =IFERROR(MIN(ROUNDDOWN(SUM(BQ7:BS7),0),6),"") -> 0 | BV7: =IF(OR($BQ$2>=30%,$BR$2>=70%,SUM(BQ7:BR7)>=7),"EP","")
G8: Ton Hours | H8: 3.5169988 | Q8: Unbundled: Green-e EACs | S8: Leased | T8: Leased | V8: On-site landfill gas - thermal* | W8: Thermal | Y8: Biofuel electricity* | AA8: Biofuel electricity* | AB8: Electricity | AE8: 6 | AF8: 6 | AM8: kBtu to kWh | AN8: =1/3.412 -> 0.29308324 | AQ8: =AQ7+0.1 -> 0.5 | AR8: 0.0095 | AS8: =AQ8/10-0.0005 -> 0.0495 | AT8: =AT7+2.5% -> 0.13445 | AU8: =AQ8 -> 0.5 | AX8: =AX7+0.2 -> 1 | AY8: 0.0095 | AZ8: 0.0295 | BA8: 0.0995 | BB8: =AX8 -> 1 | BD8: =BD7+0.1 -> 0.5 | BE8: 0.0095 | BF8: =BD8/10-0.0005 -> 0.0495 | BG8: =BG7+2.5% -> 0.12445 | BH8: =BD8 -> 0.5 | BJ8: BD+C: Hospitality | BK8: BDC
Q9: Unbundled: Green-e equivalent EACs* | S9: Owned | T9: Owned | V9: Geothermal heating (not geoexchange) | W9: Thermal | Y9: Other - Decribe* | AA9: Renewable electricity mix | AB9: Electricity | AE9: 5 | AF9: 5 | AQ9: =AQ8+0.1 -> 0.6 | AR9: 0.0115 | AS9: =AQ9/10-0.0005 -> 0.0595 | AT9: =AT8+2.5% -> 0.15945 | AU9: =AQ9 -> 0.6 | AX9: =AX8+0.2 -> 1.2 | AY9: 0.0135 | AZ9: 0.0355 | BA9: 0.1195 | BB9: =AX9 -> 1.2 | BD9: =BD8+0.1 -> 0.6 | BE9: 0.0115 | BF9: =BD9/10-0.0005 -> 0.0595 | BG9: =BG8+2.5% -> 0.14945 | BH9: =BD9 -> 0.6 | BJ9: BD+C: Warehouses and Distribution | BK9: BDC
G10: =IF(IP_SI_Units="IP Units","kWh","kWh") -> kWh | H10: Default Electricity | Q10: Other - Describe | S10: Other - Describe | T10: Other - Describe | V10: On-site untreated wood waste - electric | W10: Electricity | AA10: Recovered bio-methane* | AB10: =E3 -> Fossil Fuel | AE10: 4 | AF10: 4 | AM10: kbtu/ft2 to kWh/m2 | AN10: =AN8/AN7 -> 3.1547217 | AQ10: =AQ9+0.1 -> 0.7 | AR10: 0.0135 | AS10: =AQ10/10-0.0005 -> 0.0695 | AT10: =AT9+2.5% -> 0.18445 | AU10: =AQ10 -> 0.7 | AX10: =AX9+0.2 -> 1.4 | AY10: 0.0175 | AZ10: 0.0415 | BA10: 0.1395 | BB10: =AX10 -> 1.4 | BD10: =BD9+0.1 -> 0.7 | BE10: 0.0135 | BF10: =BD10/10-0.0005 -> 0.0695 | BG10: =BG9+2.5% -> 0.17445 | BH10: =BD10 -> 0.7 | BJ10: ID+C: Commercial Interiors | BK10: IDC
G11: =IF(IP_SI_Units="IP Units","therm","kWh") -> therm | H11: Default Fossil Fuel | V11: On-site agricultural crops or waste - electric | W11: Electricity | AA11: Other - Decribe* | AE11: 3 | AF11: 3 | AQ11: =AQ10+0.1 -> 0.8 | AR11: 0.0155 | AS11: =AQ11/10-0.0005 -> 0.0795 | AT11: =AT10+2.5% -> 0.20945 | AU11: =AQ11 -> 0.8 | AX11: =AX10+0.2 -> 1.6 | AY11: 0.0215 | AZ11: 0.0475 | BA11: 0.1595 | BB11: =AX11 -> 1.6 | BD11: =BD10+0.1 -> 0.8 | BE11: 0.0155 | BF11: =BD11/10-0.0005 -> 0.0795 | BG11: =BG10+2.5% -> 0.19945 | BH11: =BD11 -> 0.8 | BJ11: ID+C: Retail | BK11: IDC
G12: =IF(IP_SI_Units="IP Units","Ton Hours","kWh") -> Ton Hours | H12: Default District Cooling | V12: On-site animal or organic waste - electric | W12: Electricity | AE12: 2 | AF12: 2 | AQ12: =AQ11+0.1 -> 0.9 | AR12: 0.0175 | AS12: =AQ12/10-0.0005 -> 0.0895 | AT12: =AT11+2.5% -> 0.23445 | AU12: =AQ12 -> 0.9 | AX12: =AX11+0.2 -> 1.8 | AY12: 0.0255 | AZ12: 0.0535 | BA12: 0.1795 | BB12: =AX12 -> 1.8 | BD12: =BD11+0.1 -> 0.9 | BE12: 0.0175 | BF12: =BD12/10-0.0005 -> 0.0895 | BG12: =BG11+2.5% -> 0.22445 | BH12: =BD12 -> 0.9 | BJ12: ID+C: Hospitality | BK12: IDC
G13: =IF(IP_SI_Units="IP Units","kBtu","kWh") -> kBtu | H13: Default District Heating | V13: On-site landfill gas - electric | W13: Electricity | AE13: 1 | AF13: 1 | AQ13: =AQ12+0.1 -> 1 | AR13: =2%-0.0005 -> 0.0195 | AS13: =AQ13/10-0.0005 -> 0.0995 | AT13: =35%-0.0005 -> 0.3495 | AU13: =AQ13 -> 1 | AX13: =AX12+0.2 -> 2 | AY13: 0.0295 | AZ13: 0.0595 | BA13: 0.1995 | BB13: =AX13 -> 2 | BD13: =BD12+0.1 -> 1 | BE13: =2%-0.0005 -> 0.0195 | BF13: =BD13/10-0.0005 -> 0.0995 | BG13: =25%-0.0005 -> 0.2495 | BH13: =BD13 -> 1
V14: Geothermal electric | W14: Electricity | AE14: N/A (owned) | AF14: 10 | AQ14: =AQ13+0.1 -> 1.1 | AR14: 0.0225 | AS14: =AQ14/10-0.0005 -> 0.1095 | AT14: =AT13+2.5% -> 0.3745 | AU14: =AQ14 -> 1.1 | AX14: =AX13+0.2 -> 2.2 | AY14: 0.0335 | AZ14: 0.0655 | BA14: 0.2195 | BB14: =AX14 -> 2.2 | BD14: =BD13+0.1 -> 1.1 | BE14: 0.0225 | BF14: =BD14/10-0.0005 -> 0.1095 | BG14: =BG13+2.5% -> 0.2745 | BH14: =BD14 -> 1.1
G15: =IF(IP_SI_Units="IP Units","Btu x 10^6","MWh") -> Btu x 10^6 | H15: Default Total | V15: Other - Describe | AQ15: =AQ14+0.1 -> 1.2 | AR15: 0.0255 | AS15: =AQ15/10-0.0005 -> 0.1195 | AT15: =AT14+2.5% -> 0.3995 | AU15: =AQ15 -> 1.2 | AX15: =AX14+0.2 -> 2.4 | AY15: 0.0375 | AZ15: 0.0715 | BA15: 0.2395 | BB15: =AX15 -> 2.4 | BD15: =BD14+0.1 -> 1.2 | BE15: 0.0255 | BF15: =BD15/10-0.0005 -> 0.1195 | BG15: =BG14+2.5% -> 0.2995 | BH15: =BD15 -> 1.2
AQ16: =AQ15+0.1 -> 1.3 | AR16: 0.0285 | AS16: =AQ16/10-0.0005 -> 0.1295 | AT16: =AT15+2.5% -> 0.4245 | AU16: =AQ16 -> 1.3 | AX16: =AX15+0.2 -> 2.6 | AY16: 0.0415 | AZ16: 0.0775 | BA16: 0.2595 | BB16: =AX16 -> 2.6 | BD16: =BD15+0.1 -> 1.3 | BE16: 0.0285 | BF16: =BD16/10-0.0005 -> 0.1295 | BG16: =BG15+2.5% -> 0.3245 | BH16: =BD16 -> 1.3
AQ17: =AQ16+0.1 -> 1.4 | AR17: 0.0315 | AS17: =AQ17/10-0.0005 -> 0.1395 | AT17: =AT16+2.5% -> 0.4495 | AU17: =AQ17 -> 1.4 | AX17: =AX16+0.2 -> 2.8 | AY17: 0.0455 | AZ17: 0.0835 | BA17: 0.2795 | BB17: =AX17 -> 2.8 | BD17: =BD16+0.1 -> 1.4 | BE17: 0.0315 | BF17: =BD17/10-0.0005 -> 0.1395 | BG17: =BG16+2.5% -> 0.3495 | BH17: =BD17 -> 1.4
AQ18: =AQ17+0.1 -> 1.5 | AR18: 0.0345 | AS18: =AQ18/10-0.0005 -> 0.1495 | AT18: =AT17+2.5% -> 0.4745 | AU18: =AQ18 -> 1.5 | AX18: =AX17+0.2 -> 3 | AY18: 0.0495 | AZ18: 0.0895 | BA18: 0.2995 | BB18: =AX18 -> 3 | BD18: =BD17+0.1 -> 1.5 | BE18: 0.0345 | BF18: =BD18/10-0.0005 -> 0.1495 | BG18: =BG17+2.5% -> 0.3745 | BH18: =BD18 -> 1.5
AM19: 0.05 | AN19: =AS5+10% -> 0.1195 | AO19: 0.7 | AP19: 2 | AQ19: =AQ18+0.1 -> 1.6 | AR19: 0.0375 | AS19: =AQ19/10-0.0005 -> 0.1595 | AT19: =AT18+2.5% -> 0.4995 | AU19: =AQ19 -> 1.6 | AX19: =AX18+0.2 -> 3.2 | AY19: 0.0595 | AZ19: 0.0955 | BB19: =AX19 -> 3.2 | BD19: =BD18+0.1 -> 1.6 | BE19: 0.0375 | BF19: =BD19/10-0.0005 -> 0.1595 | BG19: =BG18+2.5% -> 0.3995 | BH19: =BD19 -> 1.6
V20: All Renewabe Sources | AM20: 0.1 | AN20: =AN19+10% -> 0.2195 | AO20: 1 | AP20: 3 | AQ20: =AQ19+0.1 -> 1.7 | AR20: 0.0405 | AS20: =AQ20/10-0.0005 -> 0.1695 | AT20: =AT19+2.5% -> 0.5245 | AU20: =AQ20 -> 1.7 | AX20: =AX19+0.2 -> 3.4 | AY20: 0.0695 | AZ20: 0.1015 | BB20: =AX20 -> 3.4 | BD20: =BD19+0.1 -> 1.7 | BE20: 0.0405 | BF20: =BD20/10-0.0005 -> 0.1695 | BG20: =BG19+2.5% -> 0.4245 | BH20: =BD20 -> 1.7
V21: Photovoltaic | W21: Electricity | AM21: 0.15 | AN21: =AN20+10% -> 0.3195 | AP21: 4 | AQ21: =AQ20+0.1 -> 1.8 | AR21: 0.0435 | AS21: =AQ21/10-0.0005 -> 0.1795 | AT21: =AT20+2.5% -> 0.5495 | AU21: =AQ21 -> 1.8 | AX21: =AX20+0.2 -> 3.6 | AY21: 0.0795 | AZ21: 0.1075 | BB21: =AX21 -> 3.6 | BD21: =BD20+0.1 -> 1.8 | BE21: 0.0435 | BF21: =BD21/10-0.0005 -> 0.1795 | BG21: =BG20+2.5% -> 0.4495 | BH21: =BD21 -> 1.8
V22: Wind | W22: Electricity | AM22: 0.2 | AN22: =AN21+10% -> 0.4195 | AP22: 5 | AQ22: =AQ21+0.1 -> 1.9 | AR22: 0.0465 | AS22: =AQ22/10-0.0005 -> 0.1895 | AT22: =AT21+2.5% -> 0.5745 | AU22: =AQ22 -> 1.9 | AX22: =AX21+0.2 -> 3.8 | AY22: 0.0895 | AZ22: 0.1135 | BB22: =AX22 -> 3.8 | BD22: =BD21+0.1 -> 1.9 | BE22: 0.0465 | BF22: =BD22/10-0.0005 -> 0.1895 | BG22: =BG21+2.5% -> 0.4745 | BH22: =BD22 -> 1.9
V23: Solar thermal | W23: Thermal | AM23: 0.25 | AN23: =AN22+10% -> 0.5195 | AP23: Exemplary | AQ23: =AQ22+0.1 -> 2 | AR23: =5%-0.0005 -> 0.0495 | AS23: =AQ23/10-0.0005 -> 0.1995 | AT23: =70%-0.0005 -> 0.6995 | AU23: =AQ23 -> 2 | AX23: =AX22+0.2 -> 4 | AY23: 0.0995 | AZ23: 0.1195 | BB23: =AX23 -> 4 | BD23: =BD22+0.1 -> 2 | BE23: =5%-0.0005 -> 0.0495 | BF23: =BD23/10-0.0005 -> 0.1995 | BG23: =50%-0.0005 -> 0.4995 | BH23: =BD23 -> 2
V24: On-site untreated wood waste - thermal* | W24: Thermal | AQ24: =AQ23+0.1 -> 2.1 | AR24: =AR23+0.5% -> 0.0545 | AS24: =AQ24/10-0.0005 -> 0.2095 | AT24: =AT23+2.5% -> 0.7245 | AU24: =AQ24 -> 2.1 | AX24: =AX23+0.2 -> 4.2 | AY24: 0.1095 | AZ24: 0.1255 | BB24: =AX24 -> 4.2 | BD24: =BD23+0.1 -> 2.1 | BE24: =BE23+0.5% -> 0.0545 | BF24: =BD24/10-0.0005 -> 0.2095 | BG24: =BG23+2.5% -> 0.5245 | BH24: =BD24 -> 2.1
V25: On-site agricultural crops or waste - thermal* | W25: Thermal | AQ25: =AQ24+0.1 -> 2.2 | AR25: =AR24+0.5% -> 0.0595 | AS25: =AQ25/10-0.0005 -> 0.2195 | AT25: =AT24+2.5% -> 0.7495 | AU25: =AQ25 -> 2.2 | AX25: =AX24+0.2 -> 4.4 | AY25: 0.1195 | AZ25: 0.1315 | BB25: =AX25 -> 4.4 | BD25: =BD24+0.1 -> 2.2 | BE25: =BE24+0.5% -> 0.0595 | BF25: =BD25/10-0.0005 -> 0.2195 | BG25: =BG24+2.5% -> 0.5495 | BH25: =BD25 -> 2.2
V26: On-site animal or organic waste - thermal* | W26: Thermal | AQ26: =AQ25+0.1 -> 2.3 | AR26: =AR25+0.5% -> 0.0645 | AS26: =AQ26/10-0.0005 -> 0.2295 | AT26: =AT25+2.5% -> 0.7745 | AU26: =AQ26 -> 2.3 | AX26: =AX25+0.2 -> 4.6 | AY26: 0.1295 | AZ26: 0.1375 | BB26: =AX26 -> 4.6 | BD26: =BD25+0.1 -> 2.3 | BE26: =BE25+0.5% -> 0.0645 | BF26: =BD26/10-0.0005 -> 0.2295 | BG26: =BG25+2.5% -> 0.5745 | BH26: =BD26 -> 2.3
V27: On-site landfill gas - thermal* | W27: Thermal | AQ27: =AQ26+0.1 -> 2.4 | AR27: =AR26+0.5% -> 0.0695 | AS27: =AQ27/10-0.0005 -> 0.2395 | AT27: =AT26+2.5% -> 0.7995 | AU27: =AQ27 -> 2.4 | AX27: =AX26+0.2 -> 4.8 | AY27: 0.1395 | AZ27: 0.1435 | BB27: =AX27 -> 4.8 | BD27: =BD26+0.1 -> 2.4 | BE27: =BE26+0.5% -> 0.0695 | BF27: =BD27/10-0.0005 -> 0.2395 | BG27: =BG26+2.5% -> 0.5995 | BH27: =BD27 -> 2.4
V28: Geothermal heating (not geoexchange) | W28: Thermal | AQ28: =AQ27+0.1 -> 2.5 | AR28: =AR27+0.5% -> 0.0745 | AS28: =AQ28/10-0.0005 -> 0.2495 | AT28: =AT27+2.5% -> 0.8245 | AU28: =AQ28 -> 2.5 | AX28: =AX27+0.2 -> 5 | AY28: 0.1495 | AZ28: 0.1495 | BB28: =AX28 -> 5 | BD28: =BD27+0.1 -> 2.5 | BE28: =BE27+0.5% -> 0.0745 | BF28: =BD28/10-0.0005 -> 0.2495 | BG28: =BG27+2.5% -> 0.6245 | BH28: =BD28 -> 2.5
V29: On-site untreated wood waste - electric | W29: Electricity | AQ29: =AQ28+0.1 -> 2.6 | AR29: =AR28+0.5% -> 0.0795 | AS29: =AQ29/10-0.0005 -> 0.2595 | AT29: =AT28+2.5% -> 0.8495 | AU29: =AQ29 -> 2.6 | BD29: =BD28+0.1 -> 2.6 | BE29: =BE28+0.5% -> 0.0795 | BF29: =BD29/10-0.0005 -> 0.2595 | BG29: =BG28+2.5% -> 0.6495 | BH29: =BD29 -> 2.6
V30: On-site agricultural crops or waste - electric | W30: Electricity | AQ30: =AQ29+0.1 -> 2.7 | AR30: =AR29+0.5% -> 0.0845 | AS30: =AQ30/10-0.0005 -> 0.2695 | AT30: =AT29+2.5% -> 0.8745 | AU30: =AQ30 -> 2.7 | BD30: =BD29+0.1 -> 2.7 | BE30: =BE29+0.5% -> 0.0845 | BF30: =BD30/10-0.0005 -> 0.2695 | BG30: =BG29+2.5% -> 0.6745 | BH30: =BD30 -> 2.7
V31: On-site animal or organic waste - electric | W31: Electricity | AQ31: =AQ30+0.1 -> 2.8 | AR31: =AR30+0.5% -> 0.0895 | AS31: =AQ31/10-0.0005 -> 0.2795 | AT31: =AT30+2.5% -> 0.8995 | AU31: =AQ31 -> 2.8 | BD31: =BD30+0.1 -> 2.8 | BE31: =BE30+0.5% -> 0.0895 | BF31: =BD31/10-0.0005 -> 0.2795 | BG31: =BG30+2.5% -> 0.6995 | BH31: =BD31 -> 2.8
V32: On-site landfill gas - electric | W32: Electricity | AQ32: =AQ31+0.1 -> 2.9 | AR32: =AR31+0.5% -> 0.0945 | AS32: =AQ32/10-0.0005 -> 0.2895 | AT32: =AT31+2.5% -> 0.9245 | AU32: =AQ32 -> 2.9 | BD32: =BD31+0.1 -> 2.9 | BE32: =BE31+0.5% -> 0.0945 | BF32: =BD32/10-0.0005 -> 0.2895 | BG32: =BG31+2.5% -> 0.7245 | BH32: =BD32 -> 2.9
V33: Geothermal electric | W33: Electricity | AQ33: =AQ32+0.1 -> 3 | AR33: =AR32+0.5% -> 0.0995 | AS33: =AQ33/10-0.0005 -> 0.2995 | AT33: =100%-0.0005 -> 0.9995 | AU33: =AQ33 -> 3 | BD33: =BD32+0.1 -> 3 | BE33: =BE32+0.5% -> 0.0995 | BF33: =BD33/10-0.0005 -> 0.2995 | BG33: =75%-0.0005 -> 0.7495 | BH33: =BD33 -> 3
V34: Solar thermal electricity | W34: Electricity | AQ34: =AQ33+0.1 -> 3.1 | AR34: =AR33+0.5% -> 0.1045 | AS34: =AQ34/10-0.0005 -> 0.3095 | AU34: =AQ34 -> 3.1 | BD34: =BD33+0.1 -> 3.1 | BE34: =BE33+0.5% -> 0.1045 | BF34: =BD34/10-0.0005 -> 0.3095 | BG34: =BG33+2.5% -> 0.7745 | BH34: =BD34 -> 3.1
V35: Geothermal electricity* | W35: Electricity | AQ35: =AQ34+0.1 -> 3.2 | AR35: =AR34+0.5% -> 0.1095 | AS35: =AQ35/10-0.0005 -> 0.3195 | AU35: =AQ35 -> 3.2 | BD35: =BD34+0.1 -> 3.2 | BE35: =BE34+0.5% -> 0.1095 | BF35: =BD35/10-0.0005 -> 0.3195 | BG35: =BG34+2.5% -> 0.7995 | BH35: =BD35 -> 3.2
V36: Ocean-based (wave/tidal)* | W36: Electricity | AQ36: =AQ35+0.1 -> 3.3 | AR36: =AR35+0.5% -> 0.1145 | AS36: =AQ36/10-0.0005 -> 0.3295 | AU36: =AQ36 -> 3.3 | BD36: =BD35+0.1 -> 3.3 | BE36: =BE35+0.5% -> 0.1145 | BF36: =BD36/10-0.0005 -> 0.3295 | BG36: =BG35+2.5% -> 0.8245 | BH36: =BD36 -> 3.3
V37: Low-impact hydropower* | W37: Electricity | AQ37: =AQ36+0.1 -> 3.4 | AR37: =AR36+0.5% -> 0.1195 | AS37: =AQ37/10-0.0005 -> 0.3395 | AU37: =AQ37 -> 3.4 | BD37: =BD36+0.1 -> 3.4 | BE37: =BE36+0.5% -> 0.1195 | BF37: =BD37/10-0.0005 -> 0.3395 | BG37: =BG36+2.5% -> 0.8495 | BH37: =BD37 -> 3.4
V38: Biofuel electricity* | W38: Electricity | AQ38: =AQ37+0.1 -> 3.5 | AR38: =AR37+0.5% -> 0.1245 | AS38: =AQ38/10-0.0005 -> 0.3495 | AU38: =AQ38 -> 3.5 | BD38: =BD37+0.1 -> 3.5 | BE38: =BE37+0.5% -> 0.1245 | BF38: =BD38/10-0.0005 -> 0.3495 | BG38: =BG37+2.5% -> 0.8745 | BH38: =BD38 -> 3.5
V39: Green-e certified electricity mix | W39: Electricity | AQ39: =AQ38+0.1 -> 3.6 | AR39: =AR38+0.5% -> 0.1295 | AS39: =AQ39/10-0.0005 -> 0.3595 | AU39: =AQ39 -> 3.6 | BD39: =BD38+0.1 -> 3.6 | BE39: =BE38+0.5% -> 0.1295 | BF39: =BD39/10-0.0005 -> 0.3595 | BG39: =BG38+2.5% -> 0.8995 | BH39: =BD39 -> 3.6
V40: Recovered bio-methane* | W40: =E3 -> Fossil Fuel | AQ40: =AQ39+0.1 -> 3.7 | AR40: =AR39+0.5% -> 0.1345 | AS40: =AQ40/10-0.0005 -> 0.3695 | AU40: =AQ40 -> 3.7 | BD40: =BD39+0.1 -> 3.7 | BE40: =BE39+0.5% -> 0.1345 | BF40: =BD40/10-0.0005 -> 0.3695 | BG40: =BG39+2.5% -> 0.9245 | BH40: =BD40 -> 3.7
...
